<?xml version="1.0"?>
<!--
  onrobot_rg2_model_macro.xacro
  onrobot_rg_description의 동명 파일을 복사해 3건 수정
  수정 사항:
    1. right_outer_knuckle_joint: joint name 오타 및 parent/child 순서 오류 수정
    2. onrobot_rg2 매크로: has_bracket 파라미터 추가 (브라켓 유무에 따른 origin 분기)
    3. xacro:include: onrobot_rg2.xacro 경로를 m0609_rg2_bringup 내부로 변경
  onrobot_rg2.xacro: base_link + 조립 매크로(finger_links, finger_joints) 정의.
  이 파일이 onrobot_rg2.xacro를 include하며, 상위 URDF는 onrobot_rg2 매크로만 호출.
-->
<robot xmlns:xacro="http://ros.org/wiki/xacro">
  <xacro:include filename="$(find onrobot_rg_description)/urdf/onrobot_rg2_transmission.xacro" />
  <xacro:include filename="$(find onrobot_rg_description)/urdf/onrobot_rg2_gazebo.xacro" />

  <xacro:macro name="outer_knuckle" params="prefix fingerprefix">
    <link name="${prefix}${fingerprefix}_outer_knuckle">
      <inertial>
        <origin xyz="0.0 0.0 0.0" rpy="0 0 0" />
        <mass value="0.05" />
        <inertia ixx="1.0E-03" ixy="1.0E-06" ixz="1.0E-06" iyy="1.0E-03" iyz="1.0E-06" izz="1.0E-03" />
      </inertial>
      <visual>
        <origin xyz="0 0 0" rpy="0 0 0" />
        <geometry>
          <mesh filename="package://onrobot_rg_description/meshes/rg2/visual/outer_knuckle.stl" />
        </geometry>
        <material name="">
          <color rgba="0.8 0.8 0.8 1" />
        </material>
      </visual>
      <collision>
        <origin xyz="0 0 0" rpy="0 0 0" />
        <geometry>
          <mesh filename="package://onrobot_rg_description/meshes/rg2/collision/outer_knuckle.stl" />
        </geometry>
        <sdf resolution="512"/>
      </collision>
    </link>

    <gazebo reference="${prefix}${fingerprefix}_outer_knuckle">
      <mu1>0.1</mu1>
      <mu2>0.1</mu2>
      <selfCollide>false</selfCollide>
      <material>Gazebo/White</material>
    </gazebo>
  </xacro:macro>

  <xacro:macro name="inner_knuckle" params="prefix fingerprefix">
    <link name="${prefix}${fingerprefix}_inner_knuckle">
      <inertial>
        <origin xyz="0.0 0.0 0.0" rpy="0 0 0" />
        <mass value="0.05" />
        <inertia ixx="1.0E-03" ixy="1.0E-06" ixz="1.0E-06" iyy="1.0E-03" iyz="1.0E-06" izz="1.0E-03" />
      </inertial>
      <visual>
        <origin xyz="0 0 0" rpy="0 0 0" />
        <geometry>
          <mesh filename="package://onrobot_rg_description/meshes/rg2/visual/inner_knuckle.stl" />
        </geometry>
        <material name="">
          <color rgba="0.8 0.8 0.8 1" />
        </material>
      </visual>
      <collision>
        <origin xyz="0 0 0" rpy="0 0 0" />
        <geometry>
          <mesh filename="package://onrobot_rg_description/meshes/rg2/collision/inner_knuckle.stl" />
        </geometry>
        <sdf resolution="512"/>
      </collision>
    </link>

    <gazebo reference="${prefix}${fingerprefix}_inner_knuckle">
      <mu1>0.1</mu1>
      <mu2>0.1</mu2>
      <selfCollide>false</selfCollide>
      <material>Gazebo/White</material>
    </gazebo>
  </xacro:macro>

  <xacro:macro name="inner_finger" params="prefix fingerprefix">
    <link name="${prefix}${fingerprefix}_inner_finger">
      <inertial>
        <origin xyz="0.0 0.0 0.0" rpy="0 0 0" />
        <mass value="0.05" />
        <inertia ixx="1.0E-03" ixy="1.0E-06" ixz="1.0E-06" iyy="1.0E-03" iyz="1.0E-06" izz="1.0E-03" />
      </inertial>
      <visual>
        <origin xyz="0 0 0" rpy="0 0 0" />
        <geometry>
          <mesh filename="package://onrobot_rg_description/meshes/rg2/visual/inner_finger.stl" />
        </geometry>
        <material name="">
          <color rgba="0.1 0.1 0.1 1" />
        </material>
      </visual>
      <collision>
        <origin xyz="0 0 0" rpy="0 0 0" />
        <geometry>
          <mesh filename="package://onrobot_rg_description/meshes/rg2/collision/inner_finger.stl" />
        </geometry>
        <sdf resolution="512"/>
      </collision>
    </link>

    <gazebo reference="${prefix}${fingerprefix}_inner_finger">
      <kp>1000000.0</kp>
      <kd>1.0</kd>
      <mu1>1.0</mu1>
      <mu2>1.0</mu2>
      <minDepth>0.00001</minDepth>
      <selfCollide>false</selfCollide>
      <material>Gazebo/Black</material>
    </gazebo>
  </xacro:macro>

  <xacro:macro name="inner_knuckle_joint" params="prefix fingerprefix reflect">
    <joint name="${prefix}${fingerprefix}_inner_knuckle_joint" type="revolute">
      <origin xyz="0 ${reflect * -0.007678} 0.1422970" rpy="0 0 ${(reflect - 1) * pi / 2}" />
      <parent link="${prefix}base_link" />
      <child link="${prefix}${fingerprefix}_inner_knuckle" />
      <axis xyz="1 0 0" />
      <limit lower="-0.785398" upper="0.785398" velocity="100.0" effort="1000" />
      <mimic joint="${prefix}finger_joint" multiplier="-1" offset="0" />
    </joint>
  </xacro:macro>

  <xacro:macro name="inner_finger_joint" params="prefix fingerprefix">
    <joint name="${prefix}${fingerprefix}_inner_finger_joint" type="revolute">
      <origin xyz="0 ${-(0.056770-0.017178)} ${0.163974-0.125797}" rpy="0 0 0" />
      <parent link="${prefix}${fingerprefix}_outer_knuckle" />
      <child link="${prefix}${fingerprefix}_inner_finger" />
      <axis xyz="1 0 0" />
      <limit lower="-0.872665" upper="0.872665" velocity="100.0" effort="1000" />
      <mimic joint="${prefix}finger_joint" multiplier="1" offset="0" />
    </joint>
  </xacro:macro>

  <xacro:include filename="$(find m0609_rg2_bringup)/urdf/onrobot_rg2.xacro"/>


  <xacro:macro name="finger_joint" params="prefix">
    <joint name="${prefix}finger_joint" type="revolute">
      <origin xyz="0 -0.017178 0.125797" rpy="0 0 0" />
      <parent link="${prefix}base_link" />
      <child link="${prefix}left_outer_knuckle" />
      <axis xyz="-1 0 0" />
      <limit lower="-0.558505" upper="0.785398" velocity="100.0" effort="1000" />
    </joint>
    <xacro:finger_joints prefix="${prefix}" fingerprefix="left" reflect="1.0"/>
  </xacro:macro>

  <xacro:macro name="right_outer_knuckle_joint" params="prefix">
    <joint name="${prefix}right_outer_knuckle_joint" type="revolute">
      <parent link="${prefix}base_link" />
      <child link="${prefix}right_outer_knuckle" />
      <origin xyz="0 0.017178 0.125797" rpy="0 0 ${pi}" />
      <axis xyz="1 0 0" />
      <limit lower="-0.785398" upper="0.785398" velocity="100.0" effort="1000" />
      <mimic joint="${prefix}finger_joint" multiplier="-1" offset="0" />
    </joint>
    <xacro:finger_joints prefix="${prefix}" fingerprefix="right" reflect="-1.0"/>
  </xacro:macro>

  <xacro:macro name="onrobot_rg2" params="prefix effector_base:=world has_bracket:=false">
    <xacro:base_link prefix="${prefix}" effector_base="${effector_base}" has_bracket="${has_bracket}"/>
    <xacro:finger_links prefix="${prefix}" fingerprefix="left"/>
    <xacro:finger_links prefix="${prefix}" fingerprefix="right"/>
    <xacro:finger_joint prefix="${prefix}"/>
    <xacro:right_outer_knuckle_joint prefix="${prefix}"/>
    <xacro:onrobot_rg2_transmission prefix="${prefix}"/>
    <xacro:onrobot_rg2_gazebo prefix="${prefix}"/>
  </xacro:macro>
</robot>
